Workbook
Name pa_cedant: INDEX(INDIRECT("'out_params'!$A$2:$BZ$60000"),0,MATCH("cedant",INDIRECT("'out_params'!$A$1:$BZ$1"),0))
Name pa_country: INDEX(INDIRECT("'out_params'!$A$2:$BZ$60000"),0,MATCH("country",INDIRECT("'out_params'!$A$1:$BZ$1"),0))
Name pa_line: INDEX(INDIRECT("'out_params'!$A$2:$BZ$60000"),0,MATCH("line",INDIRECT("'out_params'!$A$1:$BZ$1"),0))
Name pa_quote_ccy: INDEX(INDIRECT("'out_params'!$A$2:$BZ$60000"),0,MATCH("quote_ccy",INDIRECT("'out_params'!$A$1:$BZ$1"),0))
Name pa_fx_quote_to_usd: INDEX(INDIRECT("'out_params'!$A$2:$BZ$60000"),0,MATCH("fx_quote_to_usd",INDIRECT("'out_params'!$A$1:$BZ$1"),0))
Name pa_treaty_start: INDEX(INDIRECT("'out_params'!$A$2:$BZ$60000"),0,MATCH("treaty_start",INDIRECT("'out_params'!$A$1:$BZ$1"),0))
Name pa_quote_year: INDEX(INDIRECT("'out_params'!$A$2:$BZ$60000"),0,MATCH("quote_year",INDIRECT("'out_params'!$A$1:$BZ$1"),0))
Name pa_run_label: INDEX(INDIRECT("'out_params'!$A$2:$BZ$60000"),0,MATCH("run_label",INDIRECT("'out_params'!$A$1:$BZ$1"),0))
Name pa_scenario_id: INDEX(INDIRECT("'out_params'!$A$2:$BZ$60000"),0,MATCH("scenario_id",INDIRECT("'out_params'!$A$1:$BZ$1"),0))
Name pa_source_mode: INDEX(INDIRECT("'out_params'!$A$2:$BZ$60000"),0,MATCH("source_mode",INDIRECT("'out_params'!$A$1:$BZ$1"),0))
Name pa_premium_basis: INDEX(INDIRECT("'out_params'!$A$2:$BZ$60000"),0,MATCH("premium_basis",INDIRECT("'out_params'!$A$1:$BZ$1"),0))
Name pa_segment_field: INDEX(INDIRECT("'out_params'!$A$2:$BZ$60000"),0,MATCH("segment_field",INDIRECT("'out_params'!$A$1:$BZ$1"),0))
Name pa_ete_tpa_filter: INDEX(INDIRECT("'out_params'!$A$2:$BZ$60000"),0,MATCH("ete_tpa_filter",INDIRECT("'out_params'!$A$1:$BZ$1"),0))
Name pa_treaty_basis: INDEX(INDIRECT("'out_params'!$A$2:$BZ$60000"),0,MATCH("treaty_basis",INDIRECT("'out_params'!$A$1:$BZ$1"),0))
Name pa_claims_trigger: INDEX(INDIRECT("'out_params'!$A$2:$BZ$60000"),0,MATCH("claims_trigger",INDIRECT("'out_params'!$A$1:$BZ$1"),0))
Name pa_paid_runoff_months: INDEX(INDIRECT("'out_params'!$A$2:$BZ$60000"),0,MATCH("paid_runoff_months",INDIRECT("'out_params'!$A$1:$BZ$1"),0))
Name pa_pp_accumulation: INDEX(INDIRECT("'out_params'!$A$2:$BZ$60000"),0,MATCH("pp_accumulation",INDIRECT("'out_params'!$A$1:$BZ$1"),0))
Name pa_epi_quote_year: INDEX(INDIRECT("'out_params'!$A$2:$BZ$60000"),0,MATCH("epi_quote_year",INDIRECT("'out_params'!$A$1:$BZ$1"),0))
Name pa_expected_lives_quote_year: INDEX(INDIRECT("'out_params'!$A$2:$BZ$60000"),0,MATCH("expected_lives_quote_year",INDIRECT("'out_params'!$A$1:$BZ$1"),0))
Name pa_years_included: INDEX(INDIRECT("'out_params'!$A$2:$BZ$60000"),0,MATCH("years_included",INDIRECT("'out_params'!$A$1:$BZ$1"),0))
Name pa_output_threshold_pct_min_ap: INDEX(INDIRECT("'out_params'!$A$2:$BZ$60000"),0,MATCH("output_threshold_pct_min_ap",INDIRECT("'out_params'!$A$1:$BZ$1"),0))
Name pa_policy_limit: INDEX(INDIRECT("'out_params'!$A$2:$BZ$60000"),0,MATCH("policy_limit",INDIRECT("'out_params'!$A$1:$BZ$1"),0))
Name pa_outlier_method: INDEX(INDIRECT("'out_params'!$A$2:$BZ$60000"),0,MATCH("outlier_method",INDIRECT("'out_params'!$A$1:$BZ$1"),0))
Name pa_outlier_value: INDEX(INDIRECT("'out_params'!$A$2:$BZ$60000"),0,MATCH("outlier_value",INDIRECT("'out_params'!$A$1:$BZ$1"),0))
Name pa_iqr_multiplier: INDEX(INDIRECT("'out_params'!$A$2:$BZ$60000"),0,MATCH("iqr_multiplier",INDIRECT("'out_params'!$A$1:$BZ$1"),0))
Name pa_full_cred_n: INDEX(INDIRECT("'out_params'!$A$2:$BZ$60000"),0,MATCH("full_cred_n",INDIRECT("'out_params'!$A$1:$BZ$1"),0))
Name pa_complement_source: INDEX(INDIRECT("'out_params'!$A$2:$BZ$60000"),0,MATCH("complement_source",INDIRECT("'out_params'!$A$1:$BZ$1"),0))
Name pa_benchmark_rate: INDEX(INDIRECT("'out_params'!$A$2:$BZ$60000"),0,MATCH("benchmark_rate",INDIRECT("'out_params'!$A$1:$BZ$1"),0))
Name pa_incidence_adj: INDEX(INDIRECT("'out_params'!$A$2:$BZ$60000"),0,MATCH("incidence_adj",INDIRECT("'out_params'!$A$1:$BZ$1"),0))
Name pa_qs_cedant_retention_pct: INDEX(INDIRECT("'out_params'!$A$2:$BZ$60000"),0,MATCH("qs_cedant_retention_pct",INDIRECT("'out_params'!$A$1:$BZ$1"),0))
Name pa_evaluate_mode: INDEX(INDIRECT("'out_params'!$A$2:$BZ$60000"),0,MATCH("evaluate_mode",INDIRECT("'out_params'!$A$1:$BZ$1"),0))
Name pa_iterations: INDEX(INDIRECT("'out_params'!$A$2:$BZ$60000"),0,MATCH("iterations",INDIRECT("'out_params'!$A$1:$BZ$1"),0))
Name pa_seed: INDEX(INDIRECT("'out_params'!$A$2:$BZ$60000"),0,MATCH("seed",INDIRECT("'out_params'!$A$1:$BZ$1"),0))
Name pa_fit_cutoff: INDEX(INDIRECT("'out_params'!$A$2:$BZ$60000"),0,MATCH("fit_cutoff",INDIRECT("'out_params'!$A$1:$BZ$1"),0))
Name pa_fit_candidates: INDEX(INDIRECT("'out_params'!$A$2:$BZ$60000"),0,MATCH("fit_candidates",INDIRECT("'out_params'!$A$1:$BZ$1"),0))
Name pa_freq_model: INDEX(INDIRECT("'out_params'!$A$2:$BZ$60000"),0,MATCH("freq_model",INDIRECT("'out_params'!$A$1:$BZ$1"),0))
Name pa_ev_freq_source: INDEX(INDIRECT("'out_params'!$A$2:$BZ$60000"),0,MATCH("ev_freq_source",INDIRECT("'out_params'!$A$1:$BZ$1"),0))
Name pa_sl_attritional_threshold: INDEX(INDIRECT("'out_params'!$A$2:$BZ$60000"),0,MATCH("sl_attritional_threshold",INDIRECT("'out_params'!$A$1:$BZ$1"),0))
Name pa_sl_cov_floor: INDEX(INDIRECT("'out_params'!$A$2:$BZ$60000"),0,MATCH("sl_cov_floor",INDIRECT("'out_params'!$A$1:$BZ$1"),0))
Name pa_sl_attritional_dist: INDEX(INDIRECT("'out_params'!$A$2:$BZ$60000"),0,MATCH("sl_attritional_dist",INDIRECT("'out_params'!$A$1:$BZ$1"),0))
Name pa_net_claims_budget: INDEX(INDIRECT("'out_params'!$A$2:$BZ$60000"),0,MATCH("net_claims_budget",INDIRECT("'out_params'!$A$1:$BZ$1"),0))
Name pa_reference_lives: INDEX(INDIRECT("'out_params'!$A$2:$BZ$60000"),0,MATCH("reference_lives",INDIRECT("'out_params'!$A$1:$BZ$1"),0))
Name pa_return_periods: INDEX(INDIRECT("'out_params'!$A$2:$BZ$60000"),0,MATCH("return_periods",INDIRECT("'out_params'!$A$1:$BZ$1"),0))
Name pa_currency_display: INDEX(INDIRECT("'out_params'!$A$2:$BZ$60000"),0,MATCH("currency_display",INDIRECT("'out_params'!$A$1:$BZ$1"),0))
Name lo_cover: INDEX(INDIRECT("'out_loadings'!$A$2:$BZ$60000"),0,MATCH("cover",INDIRECT("'out_loadings'!$A$1:$BZ$1"),0))
Name lo_reinsurer_expense_pct: INDEX(INDIRECT("'out_loadings'!$A$2:$BZ$60000"),0,MATCH("reinsurer_expense_pct",INDIRECT("'out_loadings'!$A$1:$BZ$1"),0))
Name lo_brokerage_pct: INDEX(INDIRECT("'out_loadings'!$A$2:$BZ$60000"),0,MATCH("brokerage_pct",INDIRECT("'out_loadings'!$A$1:$BZ$1"),0))
Name lo_profit_margin_pct: INDEX(INDIRECT("'out_loadings'!$A$2:$BZ$60000"),0,MATCH("profit_margin_pct",INDIRECT("'out_loadings'!$A$1:$BZ$1"),0))
Name lo_premium_tax_pct: INDEX(INDIRECT("'out_loadings'!$A$2:$BZ$60000"),0,MATCH("premium_tax_pct",INDIRECT("'out_loadings'!$A$1:$BZ$1"),0))
Name lo_risk_load_k: INDEX(INDIRECT("'out_loadings'!$A$2:$BZ$60000"),0,MATCH("risk_load_k",INDIRECT("'out_loadings'!$A$1:$BZ$1"),0))
Name rl_item: INDEX(INDIRECT("'out_run_log'!$A$2:$BZ$60000"),0,MATCH("item",INDIRECT("'out_run_log'!$A$1:$BZ$1"),0))
Name rl_value: INDEX(INDIRECT("'out_run_log'!$A$2:$BZ$60000"),0,MATCH("value",INDIRECT("'out_run_log'!$A$1:$BZ$1"),0))
Name rl_justification: INDEX(INDIRECT("'out_run_log'!$A$2:$BZ$60000"),0,MATCH("justification",INDIRECT("'out_run_log'!$A$1:$BZ$1"),0))
Name bs_option_id: INDEX(INDIRECT("'out_bc_summary'!$A$2:$BZ$60000"),0,MATCH("option_id",INDIRECT("'out_bc_summary'!$A$1:$BZ$1"),0))
Name bs_layer: INDEX(INDIRECT("'out_bc_summary'!$A$2:$BZ$60000"),0,MATCH("layer",INDIRECT("'out_bc_summary'!$A$1:$BZ$1"),0))
Name bs_l_label: INDEX(INDIRECT("'out_bc_summary'!$A$2:$BZ$60000"),0,MATCH("l_label",INDIRECT("'out_bc_summary'!$A$1:$BZ$1"),0))
Name bs_lim_basis: INDEX(INDIRECT("'out_bc_summary'!$A$2:$BZ$60000"),0,MATCH("lim_basis",INDIRECT("'out_bc_summary'!$A$1:$BZ$1"),0))
Name bs_ap: INDEX(INDIRECT("'out_bc_summary'!$A$2:$BZ$60000"),0,MATCH("ap",INDIRECT("'out_bc_summary'!$A$1:$BZ$1"),0))
Name bs_limit: INDEX(INDIRECT("'out_bc_summary'!$A$2:$BZ$60000"),0,MATCH("limit",INDIRECT("'out_bc_summary'!$A$1:$BZ$1"),0))
Name bs_aad: INDEX(INDIRECT("'out_bc_summary'!$A$2:$BZ$60000"),0,MATCH("aad",INDIRECT("'out_bc_summary'!$A$1:$BZ$1"),0))

Sheet README
A1: XoL pricing tool - Results workbook
A2: Broker view: expected claims cost, indicative RI cost, cedant impact
A4: How it is filled
A5: 1. Copy this template once to data/output/<live|synth>/XoL_Results.xlsx (next to the stage folders).
A6: 2. Run the workflows 00 -> 01 -> 02 -> 03 -> 04 -> 05 -> 06 -> 07 in Alteryx. Stage 07 replaces the data sheets (out_*, scn_summary); close this workbook in Excel before running it.
A7: 3. Open the workbook. Every exhibit recalculates from the data sheets and the Inputs sheet.
A9: Sheets
A10: Inputs - display currency and unit, reference lives, return periods, expected-loss basis, loadings (Control values with optional overrides).
A11: Pricing - per option: expected loss (deterministic, stochastic, credibility-blended), SD, target and upfront premium, reinstatement premium, rates, exposed lives, 1-in-N recoveries exceed premium.
A12: Reinsurance Structures - Exhibit C1 (client format).
A13: Cedant Impact - Exhibit C2: surplus / (loss) against the net claims budget for the average year and the return periods, without RI and with each structure.
A14: Expiring - expiring rate trended vs indicated premium; as-if experience by treaty year.
... A21: Caveats: per-person completion factors from portfolio development may understate development above an attachment point; per-event frequency rests on few events (see credibility); the stop-loss attritional CoV rests on 2-5 annual points (floor applies). Risk transfer and capital are out of scope.

Sheet Inputs
A1: Inputs and loadings
A2: Yellow cells are optional overrides: blank uses the value from the run. Changing a loading or an override updates every exhibit without re-running Alteryx.
B4: Item | C4: From the run | D4: Override | E4: Used | F4: Note
B5: Quote currency | C5: =IFERROR(INDEX(pa_quote_ccy,1),"") | E5: =IF(D5="",C5,D5) | F5: Params quote_ccy
B6: 1 unit of quote currency in USD | C6: =IFERROR(INDEX(pa_fx_quote_to_usd,1),1) | E6: =IF(D6="",C6,D6) | F6: Params fx_quote_to_usd
B7: Display currency (QUOTE / USD) | C7: =IFERROR(INDEX(pa_currency_display,1),"QUOTE") | E7: =IF(D7="",C7,D7) | F7: Exhibits only
B8: Display unit (1, 1000, 1000000) | C8: 1000 | E8: =IF(D8="",C8,D8) | F8: Amounts in the exhibits are divided by this
B9: Reference lives | C9: =IFERROR(INDEX(el_reference_lives,1),"") | E9: =IF(D9="",C9,D9) | F9: Premium per reference lives (C1)
B10: Lives in the quote year | C10: =IFERROR(INDEX(el_lives_quote_year,1),"") | E10: =IF(D10="",C10,D10) | F10: Stage 03 projection
B11: Expected premium income (EPI) | C11: =IFERROR(INDEX(pa_epi_quote_year,1),"") | E11: =IF(D11="",C11,D11) | F11: Params epi_quote_year
B12: Net claims budget | C12: =IFERROR(INDEX(gs_budget,1),"") | E12: =IF(D12="",C12,D12) | F12: Run value: net_claims_budget, else mean simulated gross. Stop-loss attachments were set in the run
B13: Return period 1 (years) | C13: =IFERROR(VALUE(TRIM(MID(SUBSTITUTE(INDEX(pa_return_periods,1),",",REPT(" ",100)),1,100))),5) | E13: =IF(D13="",C13,D13) | F13: Params return_periods
B14: Return period 2 (years) | C14: =IFERROR(VALUE(TRIM(MID(SUBSTITUTE(INDEX(pa_return_periods,1),",",REPT(" ",100)),101,100))),50) | E14: =IF(D14="",C14,D14)
B15: Return period 3 (years) | C15: =IFERROR(VALUE(TRIM(MID(SUBSTITUTE(INDEX(pa_return_periods,1),",",REPT(" ",100)),201,100))),250) | E15: =IF(D15="",C15,D15)
B16: Expected loss used for PP / EV | C16: BLENDED | E16: =IF(D16="",C16,D16) | F16: BLENDED (credibility blend), STOCHASTIC or DETERMINISTIC. Stop loss always uses the simulation
B18: Display factor (currency / unit) | E18: =IF(E7="USD",E6,1)/E8
B19: Display currency label | E19: =IF(E7="USD","USD",E5)
B20: Scenario of this run | E20: =IFERROR(INDEX(rl_value,MATCH("scenario_name",rl_item,0)),"")
B22: Loadings from the Control workbook
B23: Cover | C23: Reinsurer expenses | D23: Brokerage | E23: Profit margin | F23: Premium tax | G23: Risk load k x SD | H23: Total %
B24: PP | C24: =SUMIFS(lo_reinsurer_expense_pct,lo_cover,$B24) | D24: =SUMIFS(lo_brokerage_pct,lo_cover,$B24) | E24: =SUMIFS(lo_profit_margin_pct,lo_cover,$B24) | F24: =SUMIFS(lo_premium_tax_pct,lo_cover,$B24) | G24: =SUMIFS(lo_risk_load_k,lo_cover,$B24) | H24: =SUM(C24:F24)
B25: EV | C25: =SUMIFS(lo_reinsurer_expense_pct,lo_cover,$B25) | D25: =SUMIFS(lo_brokerage_pct,lo_cover,$B25) | E25: =SUMIFS(lo_profit_margin_pct,lo_cover,$B25) | F25: =SUMIFS(lo_premium_tax_pct,lo_cover,$B25) | G25: =SUMIFS(lo_risk_load_k,lo_cover,$B25) | H25: =SUM(C25:F25)
B26: SL | C26: =SUMIFS(lo_reinsurer_expense_pct,lo_cover,$B26) | D26: =SUMIFS(lo_brokerage_pct,lo_cover,$B26) | E26: =SUMIFS(lo_profit_margin_pct,lo_cover,$B26) | F26: =SUMIFS(lo_premium_tax_pct,lo_cover,$B26) | G26: =SUMIFS(lo_risk_load_k,lo_cover,$B26) | H26: =SUM(C26:F26)
B28: Overrides (blank = Control value)
B29: Cover | C29: Reinsurer expenses | D29: Brokerage | E29: Profit margin | F29: Premium tax | G29: Risk load k x SD
B30: PP
B31: EV
B32: SL
B34: Loadings used
B35: Cover | C35: Reinsurer expenses | D35: Brokerage | E35: Profit margin | F35: Premium tax | G35: Risk load k x SD | H35: Total %
B36: PP | C36: =IF(C30="",C24,C30) | D36: =IF(D30="",D24,D30) | E36: =IF(E30="",E24,E30) | F36: =IF(F30="",F24,F30) | G36: =IF(G30="",G24,G30) | H36: =SUM(C36:F36)
B37: EV | C37: =IF(C31="",C25,C31) | D37: =IF(D31="",D25,D31) | E37: =IF(E31="",E25,E31) | F37: =IF(F31="",F25,F31) | G37: =IF(G31="",G25,G31) | H37: =SUM(C37:F37)
B38: SL | C38: =IF(C32="",C26,C32) | D38: =IF(D32="",D26,D32) | E38: =IF(E32="",E26,E32) | F38: =IF(F32="",F26,F32) | G38: =IF(G32="",G26,G32) | H38: =SUM(C38:F38)
B40: Premium = (expected loss + k x SD) / (1 - total %). With reinstatements, that is the expected total premium; the upfront premium P solves P x (1 + expected reinstatement usage) = target.

Sheet Pricing
A1: Indicative reinsurance premium by option
A2: Quote currency, full units. Rows show only the options in the run. E[L] by layer is summed per option; the SD is that of the option's total annual recovery.
A5: Cover | B5: Option | C5: Structure key | D5: Present | E5: Label | F5: E[L] deterministic | G5: E[L] stochastic | H5: E[L] blended | I5: E[L] used | J5: SD of recoveries | K5: k | L5: Total loading % | M5: Target premium (incl. reinst.) | N5: E[reinstatement usage] | O5: Upfront annual premium | P5: E[reinstatement premium] | Q5: Rate per life | R5: Rate % EPI | S5: Exposed lives | T5: Premium per exposed life | U5: Premium per reference lives | V5: Expected recoveries p.a. | W5: Expected cost of cover | X5: P(recoveries > premium) | Y5: Recoveries exceed premium 1 in N yrs | Z5: Upfront premium layer 1 | AA5: Upfront premium layer 2
A6: PP | B6: 1 | C6: ="1 PP "&B6 | D6: =COUNTIF(ss_struct_key,C6)>0 | E6: =IF(D6,INDEX(ss_l_label,MATCH(C6,ss_struct_key,0)),"") | F6: =IF(D6,SUMIFS(ps_expected_cost_det,ps_option_id,B6),"") | G6: =IF(D6,SUMIFS(ps_mean_recovery,ps_option_id,B6),"") | H6: =IF(D6,SUMIFS(ps_expected_loss_blended,ps_option_id,B6),"") | I6: =IF(D6,IF(Inputs!$E$16="DETERMINISTIC",F6,IF(Inputs!$E$16="STOCHASTIC",G6,H6)),"") | J6: =IF(D6,SUMIFS(ss_sd_recovery,ss_struct_key,C6),"") | K6: =Inputs!$G$36 | L6: =Inputs!$H$36 | M6: =IF(D6,(I6+K6*J6)/(1-L6),"") | N6: =IF(D6,IFERROR(SUMPRODUCT((ps_option_id=B6)*ps_mean_recovery*ps_mean_reinst_usage)/SUMIFS(ps_mean_recovery,ps_option_id,B6),0),"") | O6: =IF(D6,M6/(1+N6),"") | P6: =IF(D6,O6*N6,"") | Q6: =IF(D6,O6/Inputs!$E$10,"") | R6: =IF(D6,O6/Inputs!$E$11,"") | S6: =IF(D6,SUMIFS(el_exposed_lives,el_cover,A6,el_option_id,B6,el_layer,1),"") | T6: =IF(D6,IFERROR(O6/S6,0),"") | U6: =IF(D6,T6*Inputs!$E$9,"") | V6: =IF(D6,I6,"") | W6: =IF(D6,O6+P6-I6,"") | X6: =IF(D6,COUNTIFS(sq_struct_key,C6,sq_recovery,">"&O6)/MAX(1,COUNTIF(sq_struct_key,C6)),"") | Y6: =IF(D6,IF(X6>0,1/X6,"> 999"),"") | Z6: =IF(D6,IFERROR(O6*SUMIFS(ps_mean_recovery,ps_option_id,B6,ps_layer,1)/SUMIFS(ps_mean_recovery,ps_option_id,B6),O6),"") | AA6: =IF(D6,O6-Z6,"")
A7: PP | B7: 2 | C7: ="1 PP "&B7 | D7: =COUNTIF(ss_struct_key,C7)>0 | E7: =IF(D7,INDEX(ss_l_label,MATCH(C7,ss_struct_key,0)),"") | F7: =IF(D7,SUMIFS(ps_expected_cost_det,ps_option_id,B7),"") | G7: =IF(D7,SUMIFS(ps_mean_recovery,ps_option_id,B7),"") | H7: =IF(D7,SUMIFS(ps_expected_loss_blended,ps_option_id,B7),"") | I7: =IF(D7,IF(Inputs!$E$16="DETERMINISTIC",F7,IF(Inputs!$E$16="STOCHASTIC",G7,H7)),"") | J7: =IF(D7,SUMIFS(ss_sd_recovery,ss_struct_key,C7),"") | K7: =Inputs!$G$36 | L7: =Inputs!$H$36 | M7: =IF(D7,(I7+K7*J7)/(1-L7),"") | N7: =IF(D7,IFERROR(SUMPRODUCT((ps_option_id=B7)*ps_mean_recovery*ps_mean_reinst_usage)/SUMIFS(ps_mean_recovery,ps_option_id,B7),0),"") | O7: =IF(D7,M7/(1+N7),"") | P7: =IF(D7,O7*N7,"") | Q7: =IF(D7,O7/Inputs!$E$10,"") | R7: =IF(D7,O7/Inputs!$E$11,"") | S7: =IF(D7,SUMIFS(el_exposed_lives,el_cover,A7,el_option_id,B7,el_layer,1),"") | T7: =IF(D7,IFERROR(O7/S7,0),"") | U7: =IF(D7,T7*Inputs!$E$9,"") | V7: =IF(D7,I7,"") | W7: =IF(D7,O7+P7-I7,"") | X7: =IF(D7,COUNTIFS(sq_struct_key,C7,sq_recovery,">"&O7)/MAX(1,COUNTIF(sq_struct_key,C7)),"") | Y7: =IF(D7,IF(X7>0,1/X7,"> 999"),"") | Z7: =IF(D7,IFERROR(O7*SUMIFS(ps_mean_recovery,ps_option_id,B7,ps_layer,1)/SUMIFS(ps_mean_recovery,ps_option_id,B7),O7),"") | AA7: =IF(D7,O7-Z7,"")
A8: PP | B8: 3 | C8: ="1 PP "&B8 | D8: =COUNTIF(ss_struct_key,C8)>0 | E8: =IF(D8,INDEX(ss_l_label,MATCH(C8,ss_struct_key,0)),"") | F8: =IF(D8,SUMIFS(ps_expected_cost_det,ps_option_id,B8),"") | G8: =IF(D8,SUMIFS(ps_mean_recovery,ps_option_id,B8),"") | H8: =IF(D8,SUMIFS(ps_expected_loss_blended,ps_option_id,B8),"") | I8: =IF(D8,IF(Inputs!$E$16="DETERMINISTIC",F8,IF(Inputs!$E$16="STOCHASTIC",G8,H8)),"") | J8: =IF(D8,SUMIFS(ss_sd_recovery,ss_struct_key,C8),"") | K8: =Inputs!$G$36 | L8: =Inputs!$H$36 | M8: =IF(D8,(I8+K8*J8)/(1-L8),"") | N8: =IF(D8,IFERROR(SUMPRODUCT((ps_option_id=B8)*ps_mean_recovery*ps_mean_reinst_usage)/SUMIFS(ps_mean_recovery,ps_option_id,B8),0),"") | O8: =IF(D8,M8/(1+N8),"") | P8: =IF(D8,O8*N8,"") | Q8: =IF(D8,O8/Inputs!$E$10,"") | R8: =IF(D8,O8/Inputs!$E$11,"") | S8: =IF(D8,SUMIFS(el_exposed_lives,el_cover,A8,el_option_id,B8,el_layer,1),"") | T8: =IF(D8,IFERROR(O8/S8,0),"") | U8: =IF(D8,T8*Inputs!$E$9,"") | V8: =IF(D8,I8,"") | W8: =IF(D8,O8+P8-I8,"") | X8: =IF(D8,COUNTIFS(sq_struct_key,C8,sq_recovery,">"&O8)/MAX(1,COUNTIF(sq_struct_key,C8)),"") | Y8: =IF(D8,IF(X8>0,1/X8,"> 999"),"") | Z8: =IF(D8,IFERROR(O8*SUMIFS(ps_mean_recovery,ps_option_id,B8,ps_layer,1)/SUMIFS(ps_mean_recovery,ps_option_id,B8),O8),"") | AA8: =IF(D8,O8-Z8,"")
A9: PP | B9: 4 | C9: ="1 PP "&B9 | D9: =COUNTIF(ss_struct_key,C9)>0 | E9: =IF(D9,INDEX(ss_l_label,MATCH(C9,ss_struct_key,0)),"") | F9: =IF(D9,SUMIFS(ps_expected_cost_det,ps_option_id,B9),"") | G9: =IF(D9,SUMIFS(ps_mean_recovery,ps_option_id,B9),"") | H9: =IF(D9,SUMIFS(ps_expected_loss_blended,ps_option_id,B9),"") | I9: =IF(D9,IF(Inputs!$E$16="DETERMINISTIC",F9,IF(Inputs!$E$16="STOCHASTIC",G9,H9)),"") | J9: =IF(D9,SUMIFS(ss_sd_recovery,ss_struct_key,C9),"") | K9: =Inputs!$G$36 | L9: =Inputs!$H$36 | M9: =IF(D9,(I9+K9*J9)/(1-L9),"") | N9: =IF(D9,IFERROR(SUMPRODUCT((ps_option_id=B9)*ps_mean_recovery*ps_mean_reinst_usage)/SUMIFS(ps_mean_recovery,ps_option_id,B9),0),"") | O9: =IF(D9,M9/(1+N9),"") | P9: =IF(D9,O9*N9,"") | Q9: =IF(D9,O9/Inputs!$E$10,"") | R9: =IF(D9,O9/Inputs!$E$11,"") | S9: =IF(D9,SUMIFS(el_exposed_lives,el_cover,A9,el_option_id,B9,el_layer,1),"") | T9: =IF(D9,IFERROR(O9/S9,0),"") | U9: =IF(D9,T9*Inputs!$E$9,"") | V9: =IF(D9,I9,"") | W9: =IF(D9,O9+P9-I9,"") | X9: =IF(D9,COUNTIFS(sq_struct_key,C9,sq_recovery,">"&O9)/MAX(1,COUNTIF(sq_struct_key,C9)),"") | Y9: =IF(D9,IF(X9>0,1/X9,"> 999"),"") | Z9: =IF(D9,IFERROR(O9*SUMIFS(ps_mean_recovery,ps_option_id,B9,ps_layer,1)/SUMIFS(ps_mean_recovery,ps_option_id,B9),O9),"") | AA9: =IF(D9,O9-Z9,"")
A10: EV | B10: 1 | C10: ="3 EV "&B10 | D10: =COUNTIF(ss_struct_key,C10)>0 | E10: =IF(D10,INDEX(ss_l_label,MATCH(C10,ss_struct_key,0)),"") | F10: =IF(D10,SUMIFS(es_expected_cost_det,es_option_id,B10),"") | G10: =IF(D10,SUMIFS(es_mean_recovery,es_option_id,B10),"") | H10: =IF(D10,SUMIFS(es_expected_loss_blended,es_option_id,B10),"") | I10: =IF(D10,IF(Inputs!$E$16="DETERMINISTIC",F10,IF(Inputs!$E$16="STOCHASTIC",G10,H10)),"") | J10: =IF(D10,SUMIFS(ss_sd_recovery,ss_struct_key,C10),"") | K10: =Inputs!$G$37 | L10: =Inputs!$H$37 | M10: =IF(D10,(I10+K10*J10)/(1-L10),"") | N10: =IF(D10,IFERROR(SUMPRODUCT((es_option_id=B10)*es_mean_recovery*es_mean_reinst_usage)/SUMIFS(es_mean_recovery,es_option_id,B10),0),"") | O10: =IF(D10,M10/(1+N10),"") | P10: =IF(D10,O10*N10,"") | Q10: =IF(D10,O10/Inputs!$E$10,"") | R10: =IF(D10,O10/Inputs!$E$11,"") | S10: =IF(D10,SUMIFS(el_exposed_lives,el_cover,A10,el_option_id,B10,el_layer,1),"") | T10: =IF(D10,IFERROR(O10/S10,0),"") | U10: =IF(D10,T10*Inputs!$E$9,"") | V10: =IF(D10,I10,"") | W10: =IF(D10,O10+P10-I10,"") | X10: =IF(D10,COUNTIFS(sq_struct_key,C10,sq_recovery,">"&O10)/MAX(1,COUNTIF(sq_struct_key,C10)),"") | Y10: =IF(D10,IF(X10>0,1/X10,"> 999"),"") | Z10: =IF(D10,IFERROR(O10*SUMIFS(es_mean_recovery,es_option_id,B10,es_layer,1)/SUMIFS(es_mean_recovery,es_option_id,B10),O10),"") | AA10: =IF(D10,O10-Z10,"")
A11: EV | B11: 2 | C11: ="3 EV "&B11 | D11: =COUNTIF(ss_struct_key,C11)>0 | E11: =IF(D11,INDEX(ss_l_label,MATCH(C11,ss_struct_key,0)),"") | F11: =IF(D11,SUMIFS(es_expected_cost_det,es_option_id,B11),"") | G11: =IF(D11,SUMIFS(es_mean_recovery,es_option_id,B11),"") | H11: =IF(D11,SUMIFS(es_expected_loss_blended,es_option_id,B11),"") | I11: =IF(D11,IF(Inputs!$E$16="DETERMINISTIC",F11,IF(Inputs!$E$16="STOCHASTIC",G11,H11)),"") | J11: =IF(D11,SUMIFS(ss_sd_recovery,ss_struct_key,C11),"") | K11: =Inputs!$G$37 | L11: =Inputs!$H$37 | M11: =IF(D11,(I11+K11*J11)/(1-L11),"") | N11: =IF(D11,IFERROR(SUMPRODUCT((es_option_id=B11)*es_mean_recovery*es_mean_reinst_usage)/SUMIFS(es_mean_recovery,es_option_id,B11),0),"") | O11: =IF(D11,M11/(1+N11),"") | P11: =IF(D11,O11*N11,"") | Q11: =IF(D11,O11/Inputs!$E$10,"") | R11: =IF(D11,O11/Inputs!$E$11,"") | S11: =IF(D11,SUMIFS(el_exposed_lives,el_cover,A11,el_option_id,B11,el_layer,1),"") | T11: =IF(D11,IFERROR(O11/S11,0),"") | U11: =IF(D11,T11*Inputs!$E$9,"") | V11: =IF(D11,I11,"") | W11: =IF(D11,O11+P11-I11,"") | X11: =IF(D11,COUNTIFS(sq_struct_key,C11,sq_recovery,">"&O11)/MAX(1,COUNTIF(sq_struct_key,C11)),"") | Y11: =IF(D11,IF(X11>0,1/X11,"> 999"),"") | Z11: =IF(D11,IFERROR(O11*SUMIFS(es_mean_recovery,es_option_id,B11,es_layer,1)/SUMIFS(es_mean_recovery,es_option_id,B11),O11),"") | AA11: =IF(D11,O11-Z11,"")
A12: EV | B12: 3 | C12: ="3 EV "&B12 | D12: =COUNTIF(ss_struct_key,C12)>0 | E12: =IF(D12,INDEX(ss_l_label,MATCH(C12,ss_struct_key,0)),"") | F12: =IF(D12,SUMIFS(es_expected_cost_det,es_option_id,B12),"") | G12: =IF(D12,SUMIFS(es_mean_recovery,es_option_id,B12),"") | H12: =IF(D12,SUMIFS(es_expected_loss_blended,es_option_id,B12),"") | I12: =IF(D12,IF(Inputs!$E$16="DETERMINISTIC",F12,IF(Inputs!$E$16="STOCHASTIC",G12,H12)),"") | J12: =IF(D12,SUMIFS(ss_sd_recovery,ss_struct_key,C12),"") | K12: =Inputs!$G$37 | L12: =Inputs!$H$37 | M12: =IF(D12,(I12+K12*J12)/(1-L12),"") | N12: =IF(D12,IFERROR(SUMPRODUCT((es_option_id=B12)*es_mean_recovery*es_mean_reinst_usage)/SUMIFS(es_mean_recovery,es_option_id,B12),0),"") | O12: =IF(D12,M12/(1+N12),"") | P12: =IF(D12,O12*N12,"") | Q12: =IF(D12,O12/Inputs!$E$10,"") | R12: =IF(D12,O12/Inputs!$E$11,"") | S12: =IF(D12,SUMIFS(el_exposed_lives,el_cover,A12,el_option_id,B12,el_layer,1),"") | T12: =IF(D12,IFERROR(O12/S12,0),"") | U12: =IF(D12,T12*Inputs!$E$9,"") | V12: =IF(D12,I12,"") | W12: =IF(D12,O12+P12-I12,"") | X12: =IF(D12,COUNTIFS(sq_struct_key,C12,sq_recovery,">"&O12)/MAX(1,COUNTIF(sq_struct_key,C12)),"") | Y12: =IF(D12,IF(X12>0,1/X12,"> 999"),"") | Z12: =IF(D12,IFERROR(O12*SUMIFS(es_mean_recovery,es_option_id,B12,es_layer,1)/SUMIFS(es_mean_recovery,es_option_id,B12),O12),"") | AA12: =IF(D12,O12-Z12,"")
A13: EV | B13: 4 | C13: ="3 EV "&B13 | D13: =COUNTIF(ss_struct_key,C13)>0 | E13: =IF(D13,INDEX(ss_l_label,MATCH(C13,ss_struct_key,0)),"") | F13: =IF(D13,SUMIFS(es_expected_cost_det,es_option_id,B13),"") | G13: =IF(D13,SUMIFS(es_mean_recovery,es_option_id,B13),"") | H13: =IF(D13,SUMIFS(es_expected_loss_blended,es_option_id,B13),"") | I13: =IF(D13,IF(Inputs!$E$16="DETERMINISTIC",F13,IF(Inputs!$E$16="STOCHASTIC",G13,H13)),"") | J13: =IF(D13,SUMIFS(ss_sd_recovery,ss_struct_key,C13),"") | K13: =Inputs!$G$37 | L13: =Inputs!$H$37 | M13: =IF(D13,(I13+K13*J13)/(1-L13),"") | N13: =IF(D13,IFERROR(SUMPRODUCT((es_option_id=B13)*es_mean_recovery*es_mean_reinst_usage)/SUMIFS(es_mean_recovery,es_option_id,B13),0),"") | O13: =IF(D13,M13/(1+N13),"") | P13: =IF(D13,O13*N13,"") | Q13: =IF(D13,O13/Inputs!$E$10,"") | R13: =IF(D13,O13/Inputs!$E$11,"") | S13: =IF(D13,SUMIFS(el_exposed_lives,el_cover,A13,el_option_id,B13,el_layer,1),"") | T13: =IF(D13,IFERROR(O13/S13,0),"") | U13: =IF(D13,T13*Inputs!$E$9,"") | V13: =IF(D13,I13,"") | W13: =IF(D13,O13+P13-I13,"") | X13: =IF(D13,COUNTIFS(sq_struct_key,C13,sq_recovery,">"&O13)/MAX(1,COUNTIF(sq_struct_key,C13)),"") | Y13: =IF(D13,IF(X13>0,1/X13,"> 999"),"") | Z13: =IF(D13,IFERROR(O13*SUMIFS(es_mean_recovery,es_option_id,B13,es_layer,1)/SUMIFS(es_mean_recovery,es_option_id,B13),O13),"") | AA13: =IF(D13,O13-Z13,"")
A14: SL | B14: 1 | C14: ="2 SL "&B14 | D14: =COUNTIF(ss_struct_key,C14)>0 | E14: =IF(D14,INDEX(ss_l_label,MATCH(C14,ss_struct_key,0)),"") | F14: =IF(D14,"","") | G14: =IF(D14,SUMIFS(ss_mean_recovery,ss_struct_key,C14),"") | H14: =IF(D14,SUMIFS(ss_mean_recovery,ss_struct_key,C14),"") | I14: =IF(D14,G14,"") | J14: =IF(D14,SUMIFS(ss_sd_recovery,ss_struct_key,C14),"") | K14: =Inputs!$G$38 | L14: =Inputs!$H$38 | M14: =IF(D14,(I14+K14*J14)/(1-L14),"") | N14: =IF(D14,0,"") | O14: =IF(D14,M14/(1+N14),"") | P14: =IF(D14,O14*N14,"") | Q14: =IF(D14,O14/Inputs!$E$10,"") | R14: =IF(D14,O14/Inputs!$E$11,"") | S14: =IF(D14,SUMIFS(el_exposed_lives,el_cover,A14,el_option_id,B14,el_layer,1),"") | T14: =IF(D14,IFERROR(O14/S14,0),"") | U14: =IF(D14,T14*Inputs!$E$9,"") | V14: =IF(D14,I14,"") | W14: =IF(D14,O14+P14-I14,"") | X14: =IF(D14,COUNTIFS(sq_struct_key,C14,sq_recovery,">"&O14)/MAX(1,COUNTIF(sq_struct_key,C14)),"") | Y14: =IF(D14,IF(X14>0,1/X14,"> 999"),"") | Z14: =IF(D14,O14,"") | AA14: =IF(D14,O14-Z14,"")
A15: SL | B15: 2 | C15: ="2 SL "&B15 | D15: =COUNTIF(ss_struct_key,C15)>0 | E15: =IF(D15,INDEX(ss_l_label,MATCH(C15,ss_struct_key,0)),"") | F15: =IF(D15,"","") | G15: =IF(D15,SUMIFS(ss_mean_recovery,ss_struct_key,C15),"") | H15: =IF(D15,SUMIFS(ss_mean_recovery,ss_struct_key,C15),"") | I15: =IF(D15,G15,"") | J15: =IF(D15,SUMIFS(ss_sd_recovery,ss_struct_key,C15),"") | K15: =Inputs!$G$38 | L15: =Inputs!$H$38 | M15: =IF(D15,(I15+K15*J15)/(1-L15),"") | N15: =IF(D15,0,"") | O15: =IF(D15,M15/(1+N15),"") | P15: =IF(D15,O15*N15,"") | Q15: =IF(D15,O15/Inputs!$E$10,"") | R15: =IF(D15,O15/Inputs!$E$11,"") | S15: =IF(D15,SUMIFS(el_exposed_lives,el_cover,A15,el_option_id,B15,el_layer,1),"") | T15: =IF(D15,IFERROR(O15/S15,0),"") | U15: =IF(D15,T15*Inputs!$E$9,"") | V15: =IF(D15,I15,"") | W15: =IF(D15,O15+P15-I15,"") | X15: =IF(D15,COUNTIFS(sq_struct_key,C15,sq_recovery,">"&O15)/MAX(1,COUNTIF(sq_struct_key,C15)),"") | Y15: =IF(D15,IF(X15>0,1/X15,"> 999"),"") | Z15: =IF(D15,O15,"") | AA15: =IF(D15,O15-Z15,"")
A16: SL | B16: 3 | C16: ="2 SL "&B16 | D16: =COUNTIF(ss_struct_key,C16)>0 | E16: =IF(D16,INDEX(ss_l_label,MATCH(C16,ss_struct_key,0)),"") | F16: =IF(D16,"","") | G16: =IF(D16,SUMIFS(ss_mean_recovery,ss_struct_key,C16),"") | H16: =IF(D16,SUMIFS(ss_mean_recovery,ss_struct_key,C16),"") | I16: =IF(D16,G16,"") | J16: =IF(D16,SUMIFS(ss_sd_recovery,ss_struct_key,C16),"") | K16: =Inputs!$G$38 | L16: =Inputs!$H$38 | M16: =IF(D16,(I16+K16*J16)/(1-L16),"") | N16: =IF(D16,0,"") | O16: =IF(D16,M16/(1+N16),"") | P16: =IF(D16,O16*N16,"") | Q16: =IF(D16,O16/Inputs!$E$10,"") | R16: =IF(D16,O16/Inputs!$E$11,"") | S16: =IF(D16,SUMIFS(el_exposed_lives,el_cover,A16,el_option_id,B16,el_layer,1),"") | T16: =IF(D16,IFERROR(O16/S16,0),"") | U16: =IF(D16,T16*Inputs!$E$9,"") | V16: =IF(D16,I16,"") | W16: =IF(D16,O16+P16-I16,"") | X16: =IF(D16,COUNTIFS(sq_struct_key,C16,sq_recovery,">"&O16)/MAX(1,COUNTIF(sq_struct_key,C16)),"") | Y16: =IF(D16,IF(X16>0,1/X16,"> 999"),"") | Z16: =IF(D16,O16,"") | AA16: =IF(D16,O16-Z16,"")
A17: SL | B17: 4 | C17: ="2 SL "&B17 | D17: =COUNTIF(ss_struct_key,C17)>0 | E17: =IF(D17,INDEX(ss_l_label,MATCH(C17,ss_struct_key,0)),"") | F17: =IF(D17,"","") | G17: =IF(D17,SUMIFS(ss_mean_recovery,ss_struct_key,C17),"") | H17: =IF(D17,SUMIFS(ss_mean_recovery,ss_struct_key,C17),"") | I17: =IF(D17,G17,"") | J17: =IF(D17,SUMIFS(ss_sd_recovery,ss_struct_key,C17),"") | K17: =Inputs!$G$38 | L17: =Inputs!$H$38 | M17: =IF(D17,(I17+K17*J17)/(1-L17),"") | N17: =IF(D17,0,"") | O17: =IF(D17,M17/(1+N17),"") | P17: =IF(D17,O17*N17,"") | Q17: =IF(D17,O17/Inputs!$E$10,"") | R17: =IF(D17,O17/Inputs!$E$11,"") | S17: =IF(D17,SUMIFS(el_exposed_lives,el_cover,A17,el_option_id,B17,el_layer,1),"") | T17: =IF(D17,IFERROR(O17/S17,0),"") | U17: =IF(D17,T17*Inputs!$E$9,"") | V17: =IF(D17,I17,"") | W17: =IF(D17,O17+P17-I17,"") | X17: =IF(D17,COUNTIFS(sq_struct_key,C17,sq_recovery,">"&O17)/MAX(1,COUNTIF(sq_struct_key,C17)),"") | Y17: =IF(D17,IF(X17>0,1/X17,"> 999"),"") | Z17: =IF(D17,O17,"") | AA17: =IF(D17,O17-Z17,"")
A19: Premium is split between layers in proportion to their simulated expected recoveries (used for the reinstatement premium of each layer). 1 in N = 1 / share of the 999 simulated recovery quantiles above the premium.

Sheet Reinsurance Structures
A1: Reinsurance structures & options
A2: ="Amounts in "&Inputs!$E$19&IF(Inputs!$E$8=1000," thousands",IF(Inputs!$E$8=1000000," millions",""))&". Indicative premiums from high-level loadings (Inputs)."
B4: Option | C4: Cover | D4: Exposed lives | E4: Annual premium | F4: Premium per exposed life p.a. | G4: ="Premium per "&TEXT(Inputs!$E$9,"#,##0")&" lives" | H4: Expected recoveries p.a. | I4: Expected cost of cover | J4: Recoveries exceed premium 1 in N yrs
B5: =IF(Pricing!$D$6,"Per-person XoL "&1,"") | C5: =Pricing!$E$6 | D5: =IF(Pricing!$D$6,Pricing!$S$6,"") | E5: =IF(Pricing!$D$6,Pricing!$O$6*Inputs!$E$18,"") | F5: =IF(Pricing!$D$6,Pricing!$T$6*IF(Inputs!$E$7="USD",Inputs!$E$6,1),"") | G5: =IF(Pricing!$D$6,Pricing!$U$6*Inputs!$E$18,"") | H5: =IF(Pricing!$D$6,Pricing!$V$6*Inputs!$E$18,"") | I5: =IF(Pricing!$D$6,Pricing!$W$6*Inputs!$E$18,"") | J5: =IF(Pricing!$D$6,Pricing!$Y$6,"")
B6: =IF(Pricing!$D$7,"Per-person XoL "&2,"") | C6: =Pricing!$E$7 | D6: =IF(Pricing!$D$7,Pricing!$S$7,"") | E6: =IF(Pricing!$D$7,Pricing!$O$7*Inputs!$E$18,"") | F6: =IF(Pricing!$D$7,Pricing!$T$7*IF(Inputs!$E$7="USD",Inputs!$E$6,1),"") | G6: =IF(Pricing!$D$7,Pricing!$U$7*Inputs!$E$18,"") | H6: =IF(Pricing!$D$7,Pricing!$V$7*Inputs!$E$18,"") | I6: =IF(Pricing!$D$7,Pricing!$W$7*Inputs!$E$18,"") | J6: =IF(Pricing!$D$7,Pricing!$Y$7,"")
B7: =IF(Pricing!$D$8,"Per-person XoL "&3,"") | C7: =Pricing!$E$8 | D7: =IF(Pricing!$D$8,Pricing!$S$8,"") | E7: =IF(Pricing!$D$8,Pricing!$O$8*Inputs!$E$18,"") | F7: =IF(Pricing!$D$8,Pricing!$T$8*IF(Inputs!$E$7="USD",Inputs!$E$6,1),"") | G7: =IF(Pricing!$D$8,Pricing!$U$8*Inputs!$E$18,"") | H7: =IF(Pricing!$D$8,Pricing!$V$8*Inputs!$E$18,"") | I7: =IF(Pricing!$D$8,Pricing!$W$8*Inputs!$E$18,"") | J7: =IF(Pricing!$D$8,Pricing!$Y$8,"")
B8: =IF(Pricing!$D$9,"Per-person XoL "&4,"") | C8: =Pricing!$E$9 | D8: =IF(Pricing!$D$9,Pricing!$S$9,"") | E8: =IF(Pricing!$D$9,Pricing!$O$9*Inputs!$E$18,"") | F8: =IF(Pricing!$D$9,Pricing!$T$9*IF(Inputs!$E$7="USD",Inputs!$E$6,1),"") | G8: =IF(Pricing!$D$9,Pricing!$U$9*Inputs!$E$18,"") | H8: =IF(Pricing!$D$9,Pricing!$V$9*Inputs!$E$18,"") | I8: =IF(Pricing!$D$9,Pricing!$W$9*Inputs!$E$18,"") | J8: =IF(Pricing!$D$9,Pricing!$Y$9,"")
B9: =IF(Pricing!$D$10,"Per-event XoL "&1,"") | C9: =Pricing!$E$10 | D9: =IF(Pricing!$D$10,Pricing!$S$10,"") | E9: =IF(Pricing!$D$10,Pricing!$O$10*Inputs!$E$18,"") | F9: =IF(Pricing!$D$10,Pricing!$T$10*IF(Inputs!$E$7="USD",Inputs!$E$6,1),"") | G9: =IF(Pricing!$D$10,Pricing!$U$10*Inputs!$E$18,"") | H9: =IF(Pricing!$D$10,Pricing!$V$10*Inputs!$E$18,"") | I9: =IF(Pricing!$D$10,Pricing!$W$10*Inputs!$E$18,"") | J9: =IF(Pricing!$D$10,Pricing!$Y$10,"")
B10: =IF(Pricing!$D$11,"Per-event XoL "&2,"") | C10: =Pricing!$E$11 | D10: =IF(Pricing!$D$11,Pricing!$S$11,"") | E10: =IF(Pricing!$D$11,Pricing!$O$11*Inputs!$E$18,"") | F10: =IF(Pricing!$D$11,Pricing!$T$11*IF(Inputs!$E$7="USD",Inputs!$E$6,1),"") | G10: =IF(Pricing!$D$11,Pricing!$U$11*Inputs!$E$18,"") | H10: =IF(Pricing!$D$11,Pricing!$V$11*Inputs!$E$18,"") | I10: =IF(Pricing!$D$11,Pricing!$W$11*Inputs!$E$18,"") | J10: =IF(Pricing!$D$11,Pricing!$Y$11,"")
B11: =IF(Pricing!$D$12,"Per-event XoL "&3,"") | C11: =Pricing!$E$12 | D11: =IF(Pricing!$D$12,Pricing!$S$12,"") | E11: =IF(Pricing!$D$12,Pricing!$O$12*Inputs!$E$18,"") | F11: =IF(Pricing!$D$12,Pricing!$T$12*IF(Inputs!$E$7="USD",Inputs!$E$6,1),"") | G11: =IF(Pricing!$D$12,Pricing!$U$12*Inputs!$E$18,"") | H11: =IF(Pricing!$D$12,Pricing!$V$12*Inputs!$E$18,"") | I11: =IF(Pricing!$D$12,Pricing!$W$12*Inputs!$E$18,"") | J11: =IF(Pricing!$D$12,Pricing!$Y$12,"")
B12: =IF(Pricing!$D$13,"Per-event XoL "&4,"") | C12: =Pricing!$E$13 | D12: =IF(Pricing!$D$13,Pricing!$S$13,"") | E12: =IF(Pricing!$D$13,Pricing!$O$13*Inputs!$E$18,"") | F12: =IF(Pricing!$D$13,Pricing!$T$13*IF(Inputs!$E$7="USD",Inputs!$E$6,1),"") | G12: =IF(Pricing!$D$13,Pricing!$U$13*Inputs!$E$18,"") | H12: =IF(Pricing!$D$13,Pricing!$V$13*Inputs!$E$18,"") | I12: =IF(Pricing!$D$13,Pricing!$W$13*Inputs!$E$18,"") | J12: =IF(Pricing!$D$13,Pricing!$Y$13,"")
B13: =IF(Pricing!$D$14,"Stop loss "&1,"") | C13: =IF(Pricing!$D$14,IFERROR(IF(INDEX(ss_sl_measure,MATCH("2 SL "&1,ss_struct_key,0))="PCT_BUDGET",TEXT(SUMIFS(ss_limit_pct_budget,ss_struct_key,"2 SL "&1),"0%")&" xs "&TEXT(SUMIFS(ss_ap_pct_budget,ss_struct_key,"2 SL "&1),"0%")&" of budget ("&Inputs!$E$19&" "&TEXT(SUMIFS(ss_limit_amount,ss_struct_key,"2 SL "&1)*IF(Inputs!$E$7="USD",Inputs!$E$6,1)/1000000,"#,##0.0")&"m xs "&Inputs!$E$19&" "&TEXT(SUMIFS(ss_ap_amount,ss_struct_key,"2 SL "&1)*IF(Inputs!$E$7="USD",Inputs!$E$6,1)/1000000,"#,##0.0")&"m"&")",IF(INDEX(ss_sl_measure,MATCH("2 SL "&1,ss_struct_key,0))="PCT_EPI",TEXT(SUMIFS(ss_limit_pct_epi,ss_struct_key,"2 SL "&1),"0%")&" xs "&TEXT(SUMIFS(ss_ap_pct_epi,ss_struct_key,"2 SL "&1),"0%")&" of EPI ("&Inputs!$E$19&" "&TEXT(SUMIFS(ss_limit_amount,ss_struct_key,"2 SL "&1)*IF(Inputs!$E$7="USD",Inputs!$E$6,1)/1000000,"#,##0.0")&"m xs "&Inputs!$E$19&" "&TEXT(SUMIFS(ss_ap_amount,ss_struct_key,"2 SL "&1)*IF(Inputs!$E$7="USD",Inputs!$E$6,1)/1000000,"#,##0.0")&"m"&")",Inputs!$E$19&" "&TEXT(SUMIFS(ss_limit_amount,ss_struct_key,"2 SL "&1)*IF(Inputs!$E$7="USD",Inputs!$E$6,1)/1000000,"#,##0.0")&"m xs "&Inputs!$E$19&" "&TEXT(SUMIFS(ss_ap_amount,ss_struct_key,"2 SL "&1)*IF(Inputs!$E$7="USD",Inputs!$E$6,1)/1000000,"#,##0.0")&"m"))&IF(INDEX(ss_pp_option,MATCH("2 SL "&1,ss_struct_key,0))>0," net of XoL",""),Pricing!$E$14),"") | D13: =IF(Pricing!$D$14,Pricing!$S$14,"") | E13: =IF(Pricing!$D$14,Pricing!$O$14*Inputs!$E$18,"") | F13: =IF(Pricing!$D$14,Pricing!$T$14*IF(Inputs!$E$7="USD",Inputs!$E$6,1),"") | G13: =IF(Pricing!$D$14,Pricing!$U$14*Inputs!$E$18,"") | H13: =IF(Pricing!$D$14,Pricing!$V$14*Inputs!$E$18,"") | I13: =IF(Pricing!$D$14,Pricing!$W$14*Inputs!$E$18,"") | J13: =IF(Pricing!$D$14,Pricing!$Y$14,"")
B14: =IF(Pricing!$D$15,"Stop loss "&2,"") | C14: =IF(Pricing!$D$15,IFERROR(IF(INDEX(ss_sl_measure,MATCH("2 SL "&2,ss_struct_key,0))="PCT_BUDGET",TEXT(SUMIFS(ss_limit_pct_budget,ss_struct_key,"2 SL "&2),"0%")&" xs "&TEXT(SUMIFS(ss_ap_pct_budget,ss_struct_key,"2 SL "&2),"0%")&" of budget ("&Inputs!$E$19&" "&TEXT(SUMIFS(ss_limit_amount,ss_struct_key,"2 SL "&2)*IF(Inputs!$E$7="USD",Inputs!$E$6,1)/1000000,"#,##0.0")&"m xs "&Inputs!$E$19&" "&TEXT(SUMIFS(ss_ap_amount,ss_struct_key,"2 SL "&2)*IF(Inputs!$E$7="USD",Inputs!$E$6,1)/1000000,"#,##0.0")&"m"&")",IF(INDEX(ss_sl_measure,MATCH("2 SL "&2,ss_struct_key,0))="PCT_EPI",TEXT(SUMIFS(ss_limit_pct_epi,ss_struct_key,"2 SL "&2),"0%")&" xs "&TEXT(SUMIFS(ss_ap_pct_epi,ss_struct_key,"2 SL "&2),"0%")&" of EPI ("&Inputs!$E$19&" "&TEXT(SUMIFS(ss_limit_amount,ss_struct_key,"2 SL "&2)*IF(Inputs!$E$7="USD",Inputs!$E$6,1)/1000000,"#,##0.0")&"m xs "&Inputs!$E$19&" "&TEXT(SUMIFS(ss_ap_amount,ss_struct_key,"2 SL "&2)*IF(Inputs!$E$7="USD",Inputs!$E$6,1)/1000000,"#,##0.0")&"m"&")",Inputs!$E$19&" "&TEXT(SUMIFS(ss_limit_amount,ss_struct_key,"2 SL "&2)*IF(Inputs!$E$7="USD",Inputs!$E$6,1)/1000000,"#,##0.0")&"m xs "&Inputs!$E$19&" "&TEXT(SUMIFS(ss_ap_amount,ss_struct_key,"2 SL "&2)*IF(Inputs!$E$7="USD",Inputs!$E$6,1)/1000000,"#,##0.0")&"m"))&IF(INDEX(ss_pp_option,MATCH("2 SL "&2,ss_struct_key,0))>0," net of XoL",""),Pricing!$E$15),"") | D14: =IF(Pricing!$D$15,Pricing!$S$15,"") | E14: =IF(Pricing!$D$15,Pricing!$O$15*Inputs!$E$18,"") | F14: =IF(Pricing!$D$15,Pricing!$T$15*IF(Inputs!$E$7="USD",Inputs!$E$6,1),"") | G14: =IF(Pricing!$D$15,Pricing!$U$15*Inputs!$E$18,"") | H14: =IF(Pricing!$D$15,Pricing!$V$15*Inputs!$E$18,"") | I14: =IF(Pricing!$D$15,Pricing!$W$15*Inputs!$E$18,"") | J14: =IF(Pricing!$D$15,Pricing!$Y$15,"")
B15: =IF(Pricing!$D$16,"Stop loss "&3,"") | C15: =IF(Pricing!$D$16,IFERROR(IF(INDEX(ss_sl_measure,MATCH("2 SL "&3,ss_struct_key,0))="PCT_BUDGET",TEXT(SUMIFS(ss_limit_pct_budget,ss_struct_key,"2 SL "&3),"0%")&" xs "&TEXT(SUMIFS(ss_ap_pct_budget,ss_struct_key,"2 SL "&3),"0%")&" of budget ("&Inputs!$E$19&" "&TEXT(SUMIFS(ss_limit_amount,ss_struct_key,"2 SL "&3)*IF(Inputs!$E$7="USD",Inputs!$E$6,1)/1000000,"#,##0.0")&"m xs "&Inputs!$E$19&" "&TEXT(SUMIFS(ss_ap_amount,ss_struct_key,"2 SL "&3)*IF(Inputs!$E$7="USD",Inputs!$E$6,1)/1000000,"#,##0.0")&"m"&")",IF(INDEX(ss_sl_measure,MATCH("2 SL "&3,ss_struct_key,0))="PCT_EPI",TEXT(SUMIFS(ss_limit_pct_epi,ss_struct_key,"2 SL "&3),"0%")&" xs "&TEXT(SUMIFS(ss_ap_pct_epi,ss_struct_key,"2 SL "&3),"0%")&" of EPI ("&Inputs!$E$19&" "&TEXT(SUMIFS(ss_limit_amount,ss_struct_key,"2 SL "&3)*IF(Inputs!$E$7="USD",Inputs!$E$6,1)/1000000,"#,##0.0")&"m xs "&Inputs!$E$19&" "&TEXT(SUMIFS(ss_ap_amount,ss_struct_key,"2 SL "&3)*IF(Inputs!$E$7="USD",Inputs!$E$6,1)/1000000,"#,##0.0")&"m"&")",Inputs!$E$19&" "&TEXT(SUMIFS(ss_limit_amount,ss_struct_key,"2 SL "&3)*IF(Inputs!$E$7="USD",Inputs!$E$6,1)/1000000,"#,##0.0")&"m xs "&Inputs!$E$19&" "&TEXT(SUMIFS(ss_ap_amount,ss_struct_key,"2 SL "&3)*IF(Inputs!$E$7="USD",Inputs!$E$6,1)/1000000,"#,##0.0")&"m"))&IF(INDEX(ss_pp_option,MATCH("2 SL "&3,ss_struct_key,0))>0," net of XoL",""),Pricing!$E$16),"") | D15: =IF(Pricing!$D$16,Pricing!$S$16,"") | E15: =IF(Pricing!$D$16,Pricing!$O$16*Inputs!$E$18,"") | F15: =IF(Pricing!$D$16,Pricing!$T$16*IF(Inputs!$E$7="USD",Inputs!$E$6,1),"") | G15: =IF(Pricing!$D$16,Pricing!$U$16*Inputs!$E$18,"") | H15: =IF(Pricing!$D$16,Pricing!$V$16*Inputs!$E$18,"") | I15: =IF(Pricing!$D$16,Pricing!$W$16*Inputs!$E$18,"") | J15: =IF(Pricing!$D$16,Pricing!$Y$16,"")
B16: =IF(Pricing!$D$17,"Stop loss "&4,"") | C16: =IF(Pricing!$D$17,IFERROR(IF(INDEX(ss_sl_measure,MATCH("2 SL "&4,ss_struct_key,0))="PCT_BUDGET",TEXT(SUMIFS(ss_limit_pct_budget,ss_struct_key,"2 SL "&4),"0%")&" xs "&TEXT(SUMIFS(ss_ap_pct_budget,ss_struct_key,"2 SL "&4),"0%")&" of budget ("&Inputs!$E$19&" "&TEXT(SUMIFS(ss_limit_amount,ss_struct_key,"2 SL "&4)*IF(Inputs!$E$7="USD",Inputs!$E$6,1)/1000000,"#,##0.0")&"m xs "&Inputs!$E$19&" "&TEXT(SUMIFS(ss_ap_amount,ss_struct_key,"2 SL "&4)*IF(Inputs!$E$7="USD",Inputs!$E$6,1)/1000000,"#,##0.0")&"m"&")",IF(INDEX(ss_sl_measure,MATCH("2 SL "&4,ss_struct_key,0))="PCT_EPI",TEXT(SUMIFS(ss_limit_pct_epi,ss_struct_key,"2 SL "&4),"0%")&" xs "&TEXT(SUMIFS(ss_ap_pct_epi,ss_struct_key,"2 SL "&4),"0%")&" of EPI ("&Inputs!$E$19&" "&TEXT(SUMIFS(ss_limit_amount,ss_struct_key,"2 SL "&4)*IF(Inputs!$E$7="USD",Inputs!$E$6,1)/1000000,"#,##0.0")&"m xs "&Inputs!$E$19&" "&TEXT(SUMIFS(ss_ap_amount,ss_struct_key,"2 SL "&4)*IF(Inputs!$E$7="USD",Inputs!$E$6,1)/1000000,"#,##0.0")&"m"&")",Inputs!$E$19&" "&TEXT(SUMIFS(ss_limit_amount,ss_struct_key,"2 SL "&4)*IF(Inputs!$E$7="USD",Inputs!$E$6,1)/1000000,"#,##0.0")&"m xs "&Inputs!$E$19&" "&TEXT(SUMIFS(ss_ap_amount,ss_struct_key,"2 SL "&4)*IF(Inputs!$E$7="USD",Inputs!$E$6,1)/1000000,"#,##0.0")&"m"))&IF(INDEX(ss_pp_option,MATCH("2 SL "&4,ss_struct_key,0))>0," net of XoL",""),Pricing!$E$17),"") | D16: =IF(Pricing!$D$17,Pricing!$S$17,"") | E16: =IF(Pricing!$D$17,Pricing!$O$17*Inputs!$E$18,"") | F16: =IF(Pricing!$D$17,Pricing!$T$17*IF(Inputs!$E$7="USD",Inputs!$E$6,1),"") | G16: =IF(Pricing!$D$17,Pricing!$U$17*Inputs!$E$18,"") | H16: =IF(Pricing!$D$17,Pricing!$V$17*Inputs!$E$18,"") | I16: =IF(Pricing!$D$17,Pricing!$W$17*Inputs!$E$18,"") | J16: =IF(Pricing!$D$17,Pricing!$Y$17,"")
B18: Premium per exposed life is in the display currency, full units. Per-person exposed lives are lives whose benefit limit exceeds the attachment point; stop loss and per-event use all lives.

Sheet Cedant Impact
A1: Cedant impact: surplus / (loss) against the net claims budget
A2: ="Amounts in "&Inputs!$E$19&IF(Inputs!$E$8=1000," thousands",IF(Inputs!$E$8=1000000," millions",""))&". Surplus = budget - (claims net of recoveries + RI premium incl. reinstatement premium); return-period values are quantiles of the joint simulated outcome."
B5: Structure key | C5: 0 NONE | D5: 1 PP 1 | E5: 1 PP 2 | F5: 1 PP 3 | G5: 1 PP 4 | H5: 3 EV 1 | I5: 3 EV 2 | J5: 3 EV 3 | K5: 3 EV 4 | L5: 2 SL 1 | M5: 2 SL 2 | N5: 2 SL 3 | O5: 2 SL 4 | P5: 4 PROGRAMME
B6: Structure | C6: =IF(COUNTIF(ss_struct_key,C$5)>0,INDEX(ss_l_label,MATCH(C$5,ss_struct_key,0))&IF(AND(LEFT(C$5,1)="2",C18+C19>0)," + XoL","") ,"") | D6: =IF(COUNTIF(ss_struct_key,D$5)>0,INDEX(ss_l_label,MATCH(D$5,ss_struct_key,0))&IF(AND(LEFT(D$5,1)="2",D18+D19>0)," + XoL","") ,"") | E6: =IF(COUNTIF(ss_struct_key,E$5)>0,INDEX(ss_l_label,MATCH(E$5,ss_struct_key,0))&IF(AND(LEFT(E$5,1)="2",E18+E19>0)," + XoL","") ,"") | F6: =IF(COUNTIF(ss_struct_key,F$5)>0,INDEX(ss_l_label,MATCH(F$5,ss_struct_key,0))&IF(AND(LEFT(F$5,1)="2",F18+F19>0)," + XoL","") ,"") | G6: =IF(COUNTIF(ss_struct_key,G$5)>0,INDEX(ss_l_label,MATCH(G$5,ss_struct_key,0))&IF(AND(LEFT(G$5,1)="2",G18+G19>0)," + XoL","") ,"") | H6: =IF(COUNTIF(ss_struct_key,H$5)>0,INDEX(ss_l_label,MATCH(H$5,ss_struct_key,0))&IF(AND(LEFT(H$5,1)="2",H18+H19>0)," + XoL","") ,"") | I6: =IF(COUNTIF(ss_struct_key,I$5)>0,INDEX(ss_l_label,MATCH(I$5,ss_struct_key,0))&IF(AND(LEFT(I$5,1)="2",I18+I19>0)," + XoL","") ,"") | J6: =IF(COUNTIF(ss_struct_key,J$5)>0,INDEX(ss_l_label,MATCH(J$5,ss_struct_key,0))&IF(AND(LEFT(J$5,1)="2",J18+J19>0)," + XoL","") ,"") | ... P6: =IF(COUNTIF(ss_struct_key,P$5)>0,INDEX(ss_l_label,MATCH(P$5,ss_struct_key,0))&IF(AND(LEFT(P$5,1)="2",P18+P19>0)," + XoL","") ,"")
B7: Annual RI premium (incl. expected reinstatement premium) | C7: =IF(COUNTIF(ss_struct_key,C$5)>0,(C26+C27)*Inputs!$E$18,"") | D7: =IF(COUNTIF(ss_struct_key,D$5)>0,(D26+D27)*Inputs!$E$18,"") | E7: =IF(COUNTIF(ss_struct_key,E$5)>0,(E26+E27)*Inputs!$E$18,"") | F7: =IF(COUNTIF(ss_struct_key,F$5)>0,(F26+F27)*Inputs!$E$18,"") | G7: =IF(COUNTIF(ss_struct_key,G$5)>0,(G26+G27)*Inputs!$E$18,"") | H7: =IF(COUNTIF(ss_struct_key,H$5)>0,(H26+H27)*Inputs!$E$18,"") | I7: =IF(COUNTIF(ss_struct_key,I$5)>0,(I26+I27)*Inputs!$E$18,"") | J7: =IF(COUNTIF(ss_struct_key,J$5)>0,(J26+J27)*Inputs!$E$18,"") | ... P7: =IF(COUNTIF(ss_struct_key,P$5)>0,(P26+P27)*Inputs!$E$18,"")
B8: Net claims budget | C8: =IF(COUNTIF(ss_struct_key,C$5)>0,Inputs!$E$12*Inputs!$E$18,"") | D8: =IF(COUNTIF(ss_struct_key,D$5)>0,Inputs!$E$12*Inputs!$E$18,"") | E8: =IF(COUNTIF(ss_struct_key,E$5)>0,Inputs!$E$12*Inputs!$E$18,"") | F8: =IF(COUNTIF(ss_struct_key,F$5)>0,Inputs!$E$12*Inputs!$E$18,"") | G8: =IF(COUNTIF(ss_struct_key,G$5)>0,Inputs!$E$12*Inputs!$E$18,"") | H8: =IF(COUNTIF(ss_struct_key,H$5)>0,Inputs!$E$12*Inputs!$E$18,"") | I8: =IF(COUNTIF(ss_struct_key,I$5)>0,Inputs!$E$12*Inputs!$E$18,"") | J8: =IF(COUNTIF(ss_struct_key,J$5)>0,Inputs!$E$12*Inputs!$E$18,"") | ... P8: =IF(COUNTIF(ss_struct_key,P$5)>0,Inputs!$E$12*Inputs!$E$18,"")
B10: Surplus / (loss) against the net claims budget
B11: Average year | C11: =IF(COUNTIF(ss_struct_key,C$5)>0,(Inputs!$E$12-C28-C26-C27)*Inputs!$E$18,"") | D11: =IF(COUNTIF(ss_struct_key,D$5)>0,(Inputs!$E$12-D28-D26-D27)*Inputs!$E$18,"") | E11: =IF(COUNTIF(ss_struct_key,E$5)>0,(Inputs!$E$12-E28-E26-E27)*Inputs!$E$18,"") | F11: =IF(COUNTIF(ss_struct_key,F$5)>0,(Inputs!$E$12-F28-F26-F27)*Inputs!$E$18,"") | G11: =IF(COUNTIF(ss_struct_key,G$5)>0,(Inputs!$E$12-G28-G26-G27)*Inputs!$E$18,"") | H11: =IF(COUNTIF(ss_struct_key,H$5)>0,(Inputs!$E$12-H28-H26-H27)*Inputs!$E$18,"") | I11: =IF(COUNTIF(ss_struct_key,I$5)>0,(Inputs!$E$12-I28-I26-I27)*Inputs!$E$18,"") | J11: =IF(COUNTIF(ss_struct_key,J$5)>0,(Inputs!$E$12-J28-J26-J27)*Inputs!$E$18,"") | ... P11: =IF(COUNTIF(ss_struct_key,P$5)>0,(Inputs!$E$12-P28-P26-P27)*Inputs!$E$18,"")
B12: ="1 in "&TEXT(Inputs!$E$13,"0")&" years" | C12: =IF(COUNTIF(ss_struct_key,C$5)>0,(Inputs!$E$12-C33-C26-C36)*Inputs!$E$18,"") | D12: =IF(COUNTIF(ss_struct_key,D$5)>0,(Inputs!$E$12-D33-D26-D36)*Inputs!$E$18,"") | E12: =IF(COUNTIF(ss_struct_key,E$5)>0,(Inputs!$E$12-E33-E26-E36)*Inputs!$E$18,"") | F12: =IF(COUNTIF(ss_struct_key,F$5)>0,(Inputs!$E$12-F33-F26-F36)*Inputs!$E$18,"") | G12: =IF(COUNTIF(ss_struct_key,G$5)>0,(Inputs!$E$12-G33-G26-G36)*Inputs!$E$18,"") | H12: =IF(COUNTIF(ss_struct_key,H$5)>0,(Inputs!$E$12-H33-H26-H36)*Inputs!$E$18,"") | I12: =IF(COUNTIF(ss_struct_key,I$5)>0,(Inputs!$E$12-I33-I26-I36)*Inputs!$E$18,"") | J12: =IF(COUNTIF(ss_struct_key,J$5)>0,(Inputs!$E$12-J33-J26-J36)*Inputs!$E$18,"") | ... P12: =IF(COUNTIF(ss_struct_key,P$5)>0,(Inputs!$E$12-P33-P26-P36)*Inputs!$E$18,"")
B13: ="1 in "&TEXT(Inputs!$E$14,"0")&" years" | C13: =IF(COUNTIF(ss_struct_key,C$5)>0,(Inputs!$E$12-C34-C26-C37)*Inputs!$E$18,"") | D13: =IF(COUNTIF(ss_struct_key,D$5)>0,(Inputs!$E$12-D34-D26-D37)*Inputs!$E$18,"") | E13: =IF(COUNTIF(ss_struct_key,E$5)>0,(Inputs!$E$12-E34-E26-E37)*Inputs!$E$18,"") | F13: =IF(COUNTIF(ss_struct_key,F$5)>0,(Inputs!$E$12-F34-F26-F37)*Inputs!$E$18,"") | G13: =IF(COUNTIF(ss_struct_key,G$5)>0,(Inputs!$E$12-G34-G26-G37)*Inputs!$E$18,"") | H13: =IF(COUNTIF(ss_struct_key,H$5)>0,(Inputs!$E$12-H34-H26-H37)*Inputs!$E$18,"") | I13: =IF(COUNTIF(ss_struct_key,I$5)>0,(Inputs!$E$12-I34-I26-I37)*Inputs!$E$18,"") | J13: =IF(COUNTIF(ss_struct_key,J$5)>0,(Inputs!$E$12-J34-J26-J37)*Inputs!$E$18,"") | ... P13: =IF(COUNTIF(ss_struct_key,P$5)>0,(Inputs!$E$12-P34-P26-P37)*Inputs!$E$18,"")
B14: ="1 in "&TEXT(Inputs!$E$15,"0")&" years" | C14: =IF(COUNTIF(ss_struct_key,C$5)>0,(Inputs!$E$12-C35-C26-C38)*Inputs!$E$18,"") | D14: =IF(COUNTIF(ss_struct_key,D$5)>0,(Inputs!$E$12-D35-D26-D38)*Inputs!$E$18,"") | E14: =IF(COUNTIF(ss_struct_key,E$5)>0,(Inputs!$E$12-E35-E26-E38)*Inputs!$E$18,"") | F14: =IF(COUNTIF(ss_struct_key,F$5)>0,(Inputs!$E$12-F35-F26-F38)*Inputs!$E$18,"") | G14: =IF(COUNTIF(ss_struct_key,G$5)>0,(Inputs!$E$12-G35-G26-G38)*Inputs!$E$18,"") | H14: =IF(COUNTIF(ss_struct_key,H$5)>0,(Inputs!$E$12-H35-H26-H38)*Inputs!$E$18,"") | I14: =IF(COUNTIF(ss_struct_key,I$5)>0,(Inputs!$E$12-I35-I26-I38)*Inputs!$E$18,"") | J14: =IF(COUNTIF(ss_struct_key,J$5)>0,(Inputs!$E$12-J35-J26-J38)*Inputs!$E$18,"") | ... P14: =IF(COUNTIF(ss_struct_key,P$5)>0,(Inputs!$E$12-P35-P26-P38)*Inputs!$E$18,"")
B17: Workings (quote currency, full units)
B18: PP option | C18: =IFERROR(INDEX(ss_pp_option,MATCH(C$5,ss_struct_key,0)),0) | D18: =IFERROR(INDEX(ss_pp_option,MATCH(D$5,ss_struct_key,0)),0) | E18: =IFERROR(INDEX(ss_pp_option,MATCH(E$5,ss_struct_key,0)),0) | F18: =IFERROR(INDEX(ss_pp_option,MATCH(F$5,ss_struct_key,0)),0) | G18: =IFERROR(INDEX(ss_pp_option,MATCH(G$5,ss_struct_key,0)),0) | H18: =IFERROR(INDEX(ss_pp_option,MATCH(H$5,ss_struct_key,0)),0) | I18: =IFERROR(INDEX(ss_pp_option,MATCH(I$5,ss_struct_key,0)),0) | J18: =IFERROR(INDEX(ss_pp_option,MATCH(J$5,ss_struct_key,0)),0) | ... P18: =IFERROR(INDEX(ss_pp_option,MATCH(P$5,ss_struct_key,0)),0)
B19: EV option | C19: =IFERROR(INDEX(ss_ev_option,MATCH(C$5,ss_struct_key,0)),0) | D19: =IFERROR(INDEX(ss_ev_option,MATCH(D$5,ss_struct_key,0)),0) | E19: =IFERROR(INDEX(ss_ev_option,MATCH(E$5,ss_struct_key,0)),0) | F19: =IFERROR(INDEX(ss_ev_option,MATCH(F$5,ss_struct_key,0)),0) | G19: =IFERROR(INDEX(ss_ev_option,MATCH(G$5,ss_struct_key,0)),0) | H19: =IFERROR(INDEX(ss_ev_option,MATCH(H$5,ss_struct_key,0)),0) | I19: =IFERROR(INDEX(ss_ev_option,MATCH(I$5,ss_struct_key,0)),0) | J19: =IFERROR(INDEX(ss_ev_option,MATCH(J$5,ss_struct_key,0)),0) | ... P19: =IFERROR(INDEX(ss_ev_option,MATCH(P$5,ss_struct_key,0)),0)
B20: SL option | C20: =IFERROR(INDEX(ss_sl_option,MATCH(C$5,ss_struct_key,0)),0) | D20: =IFERROR(INDEX(ss_sl_option,MATCH(D$5,ss_struct_key,0)),0) | E20: =IFERROR(INDEX(ss_sl_option,MATCH(E$5,ss_struct_key,0)),0) | F20: =IFERROR(INDEX(ss_sl_option,MATCH(F$5,ss_struct_key,0)),0) | G20: =IFERROR(INDEX(ss_sl_option,MATCH(G$5,ss_struct_key,0)),0) | H20: =IFERROR(INDEX(ss_sl_option,MATCH(H$5,ss_struct_key,0)),0) | I20: =IFERROR(INDEX(ss_sl_option,MATCH(I$5,ss_struct_key,0)),0) | J20: =IFERROR(INDEX(ss_sl_option,MATCH(J$5,ss_struct_key,0)),0) | ... P20: =IFERROR(INDEX(ss_sl_option,MATCH(P$5,ss_struct_key,0)),0)
B21: Premium PP layer 1 | C21: =IF(C18>0,INDEX(Pricing!$Z$6:$Z$9,C18),0) | D21: =IF(D18>0,INDEX(Pricing!$Z$6:$Z$9,D18),0) | E21: =IF(E18>0,INDEX(Pricing!$Z$6:$Z$9,E18),0) | F21: =IF(F18>0,INDEX(Pricing!$Z$6:$Z$9,F18),0) | G21: =IF(G18>0,INDEX(Pricing!$Z$6:$Z$9,G18),0) | H21: =IF(H18>0,INDEX(Pricing!$Z$6:$Z$9,H18),0) | I21: =IF(I18>0,INDEX(Pricing!$Z$6:$Z$9,I18),0) | J21: =IF(J18>0,INDEX(Pricing!$Z$6:$Z$9,J18),0) | ... P21: =IF(P18>0,INDEX(Pricing!$Z$6:$Z$9,P18),0)
B22: Premium PP layer 2 | C22: =IF(C18>0,INDEX(Pricing!$AA$6:$AA$9,C18),0) | D22: =IF(D18>0,INDEX(Pricing!$AA$6:$AA$9,D18),0) | E22: =IF(E18>0,INDEX(Pricing!$AA$6:$AA$9,E18),0) | F22: =IF(F18>0,INDEX(Pricing!$AA$6:$AA$9,F18),0) | G22: =IF(G18>0,INDEX(Pricing!$AA$6:$AA$9,G18),0) | H22: =IF(H18>0,INDEX(Pricing!$AA$6:$AA$9,H18),0) | I22: =IF(I18>0,INDEX(Pricing!$AA$6:$AA$9,I18),0) | J22: =IF(J18>0,INDEX(Pricing!$AA$6:$AA$9,J18),0) | ... P22: =IF(P18>0,INDEX(Pricing!$AA$6:$AA$9,P18),0)
B23: Premium EV layer 1 | C23: =IF(C19>0,INDEX(Pricing!$Z$10:$Z$13,C19),0) | D23: =IF(D19>0,INDEX(Pricing!$Z$10:$Z$13,D19),0) | E23: =IF(E19>0,INDEX(Pricing!$Z$10:$Z$13,E19),0) | F23: =IF(F19>0,INDEX(Pricing!$Z$10:$Z$13,F19),0) | G23: =IF(G19>0,INDEX(Pricing!$Z$10:$Z$13,G19),0) | H23: =IF(H19>0,INDEX(Pricing!$Z$10:$Z$13,H19),0) | I23: =IF(I19>0,INDEX(Pricing!$Z$10:$Z$13,I19),0) | J23: =IF(J19>0,INDEX(Pricing!$Z$10:$Z$13,J19),0) | ... P23: =IF(P19>0,INDEX(Pricing!$Z$10:$Z$13,P19),0)
B24: Premium EV layer 2 | C24: =IF(C19>0,INDEX(Pricing!$AA$10:$AA$13,C19),0) | D24: =IF(D19>0,INDEX(Pricing!$AA$10:$AA$13,D19),0) | E24: =IF(E19>0,INDEX(Pricing!$AA$10:$AA$13,E19),0) | F24: =IF(F19>0,INDEX(Pricing!$AA$10:$AA$13,F19),0) | G24: =IF(G19>0,INDEX(Pricing!$AA$10:$AA$13,G19),0) | H24: =IF(H19>0,INDEX(Pricing!$AA$10:$AA$13,H19),0) | I24: =IF(I19>0,INDEX(Pricing!$AA$10:$AA$13,I19),0) | J24: =IF(J19>0,INDEX(Pricing!$AA$10:$AA$13,J19),0) | ... P24: =IF(P19>0,INDEX(Pricing!$AA$10:$AA$13,P19),0)
B25: Premium SL | C25: =IF(C20>0,INDEX(Pricing!$O$14:$O$17,C20),0) | D25: =IF(D20>0,INDEX(Pricing!$O$14:$O$17,D20),0) | E25: =IF(E20>0,INDEX(Pricing!$O$14:$O$17,E20),0) | F25: =IF(F20>0,INDEX(Pricing!$O$14:$O$17,F20),0) | G25: =IF(G20>0,INDEX(Pricing!$O$14:$O$17,G20),0) | H25: =IF(H20>0,INDEX(Pricing!$O$14:$O$17,H20),0) | I25: =IF(I20>0,INDEX(Pricing!$O$14:$O$17,I20),0) | J25: =IF(J20>0,INDEX(Pricing!$O$14:$O$17,J20),0) | ... P25: =IF(P20>0,INDEX(Pricing!$O$14:$O$17,P20),0)
B26: Upfront premium | C26: =SUM(C21:C25) | D26: =SUM(D21:D25) | E26: =SUM(E21:E25) | F26: =SUM(F21:F25) | G26: =SUM(G21:G25) | H26: =SUM(H21:H25) | I26: =SUM(I21:I25) | J26: =SUM(J21:J25) | ... P26: =SUM(P21:P25)
B27: E[reinstatement premium] | C27: =C21*SUMIFS(ss_mean_ru_l1,ss_struct_key,C$5)+C22*SUMIFS(ss_mean_ru_l2,ss_struct_key,C$5)+C23*SUMIFS(ss_mean_ru_ev1,ss_struct_key,C$5)+C24*SUMIFS(ss_mean_ru_ev2,ss_struct_key,C$5) | D27: =D21*SUMIFS(ss_mean_ru_l1,ss_struct_key,D$5)+D22*SUMIFS(ss_mean_ru_l2,ss_struct_key,D$5)+D23*SUMIFS(ss_mean_ru_ev1,ss_struct_key,D$5)+D24*SUMIFS(ss_mean_ru_ev2,ss_struct_key,D$5) | E27: =E21*SUMIFS(ss_mean_ru_l1,ss_struct_key,E$5)+E22*SUMIFS(ss_mean_ru_l2,ss_struct_key,E$5)+E23*SUMIFS(ss_mean_ru_ev1,ss_struct_key,E$5)+E24*SUMIFS(ss_mean_ru_ev2,ss_struct_key,E$5) | F27: =F21*SUMIFS(ss_mean_ru_l1,ss_struct_key,F$5)+F22*SUMIFS(ss_mean_ru_l2,ss_struct_key,F$5)+F23*SUMIFS(ss_mean_ru_ev1,ss_struct_key,F$5)+F24*SUMIFS(ss_mean_ru_ev2,ss_struct_key,F$5) | G27: =G21*SUMIFS(ss_mean_ru_l1,ss_struct_key,G$5)+G22*SUMIFS(ss_mean_ru_l2,ss_struct_key,G$5)+G23*SUMIFS(ss_mean_ru_ev1,ss_struct_key,G$5)+G24*SUMIFS(ss_mean_ru_ev2,ss_struct_key,G$5) | H27: =H21*SUMIFS(ss_mean_ru_l1,ss_struct_key,H$5)+H22*SUMIFS(ss_mean_ru_l2,ss_struct_key,H$5)+H23*SUMIFS(ss_mean_ru_ev1,ss_struct_key,H$5)+H24*SUMIFS(ss_mean_ru_ev2,ss_struct_key,H$5) | I27: =I21*SUMIFS(ss_mean_ru_l1,ss_struct_key,I$5)+I22*SUMIFS(ss_mean_ru_l2,ss_struct_key,I$5)+I23*SUMIFS(ss_mean_ru_ev1,ss_struct_key,I$5)+I24*SUMIFS(ss_mean_ru_ev2,ss_struct_key,I$5) | J27: =J21*SUMIFS(ss_mean_ru_l1,ss_struct_key,J$5)+J22*SUMIFS(ss_mean_ru_l2,ss_struct_key,J$5)+J23*SUMIFS(ss_mean_ru_ev1,ss_struct_key,J$5)+J24*SUMIFS(ss_mean_ru_ev2,ss_struct_key,J$5) | ... P27: =P21*SUMIFS(ss_mean_ru_l1,ss_struct_key,P$5)+P22*SUMIFS(ss_mean_ru_l2,ss_struct_key,P$5)+P23*SUMIFS(ss_mean_ru_ev1,ss_struct_key,P$5)+P24*SUMIFS(ss_mean_ru_ev2,ss_struct_key,P$5)
B28: Mean net claims | C28: =SUMIFS(ss_mean_net,ss_struct_key,C$5) | D28: =SUMIFS(ss_mean_net,ss_struct_key,D$5) | E28: =SUMIFS(ss_mean_net,ss_struct_key,E$5) | F28: =SUMIFS(ss_mean_net,ss_struct_key,F$5) | G28: =SUMIFS(ss_mean_net,ss_struct_key,G$5) | H28: =SUMIFS(ss_mean_net,ss_struct_key,H$5) | I28: =SUMIFS(ss_mean_net,ss_struct_key,I$5) | J28: =SUMIFS(ss_mean_net,ss_struct_key,J$5) | ... P28: =SUMIFS(ss_mean_net,ss_struct_key,P$5)
A30: =ROUND(1000*(1-1/Inputs!$E$13),0) | B30: ="q (per mille), 1 in "&TEXT(Inputs!$E$13,"0")
A31: =ROUND(1000*(1-1/Inputs!$E$14),0) | B31: ="q (per mille), 1 in "&TEXT(Inputs!$E$14,"0")
A32: =ROUND(1000*(1-1/Inputs!$E$15),0) | B32: ="q (per mille), 1 in "&TEXT(Inputs!$E$15,"0")
B33: ="Net claims at 1 in "&TEXT(Inputs!$E$13,"0") | C33: =SUMIFS(sq_net_claims,sq_struct_key,C$5,sq_qm,$A$30) | D33: =SUMIFS(sq_net_claims,sq_struct_key,D$5,sq_qm,$A$30) | E33: =SUMIFS(sq_net_claims,sq_struct_key,E$5,sq_qm,$A$30) | F33: =SUMIFS(sq_net_claims,sq_struct_key,F$5,sq_qm,$A$30) | G33: =SUMIFS(sq_net_claims,sq_struct_key,G$5,sq_qm,$A$30) | H33: =SUMIFS(sq_net_claims,sq_struct_key,H$5,sq_qm,$A$30) | I33: =SUMIFS(sq_net_claims,sq_struct_key,I$5,sq_qm,$A$30) | J33: =SUMIFS(sq_net_claims,sq_struct_key,J$5,sq_qm,$A$30) | ... P33: =SUMIFS(sq_net_claims,sq_struct_key,P$5,sq_qm,$A$30)
B34: ="Net claims at 1 in "&TEXT(Inputs!$E$14,"0") | C34: =SUMIFS(sq_net_claims,sq_struct_key,C$5,sq_qm,$A$31) | D34: =SUMIFS(sq_net_claims,sq_struct_key,D$5,sq_qm,$A$31) | E34: =SUMIFS(sq_net_claims,sq_struct_key,E$5,sq_qm,$A$31) | F34: =SUMIFS(sq_net_claims,sq_struct_key,F$5,sq_qm,$A$31) | G34: =SUMIFS(sq_net_claims,sq_struct_key,G$5,sq_qm,$A$31) | H34: =SUMIFS(sq_net_claims,sq_struct_key,H$5,sq_qm,$A$31) | I34: =SUMIFS(sq_net_claims,sq_struct_key,I$5,sq_qm,$A$31) | J34: =SUMIFS(sq_net_claims,sq_struct_key,J$5,sq_qm,$A$31) | ... P34: =SUMIFS(sq_net_claims,sq_struct_key,P$5,sq_qm,$A$31)
B35: ="Net claims at 1 in "&TEXT(Inputs!$E$15,"0") | C35: =SUMIFS(sq_net_claims,sq_struct_key,C$5,sq_qm,$A$32) | D35: =SUMIFS(sq_net_claims,sq_struct_key,D$5,sq_qm,$A$32) | E35: =SUMIFS(sq_net_claims,sq_struct_key,E$5,sq_qm,$A$32) | F35: =SUMIFS(sq_net_claims,sq_struct_key,F$5,sq_qm,$A$32) | G35: =SUMIFS(sq_net_claims,sq_struct_key,G$5,sq_qm,$A$32) | H35: =SUMIFS(sq_net_claims,sq_struct_key,H$5,sq_qm,$A$32) | I35: =SUMIFS(sq_net_claims,sq_struct_key,I$5,sq_qm,$A$32) | J35: =SUMIFS(sq_net_claims,sq_struct_key,J$5,sq_qm,$A$32) | ... P35: =SUMIFS(sq_net_claims,sq_struct_key,P$5,sq_qm,$A$32)
B36: ="Reinstatement premium at 1 in "&TEXT(Inputs!$E$13,"0") | C36: =C21*SUMIFS(sq_ru_l1_at_q,sq_struct_key,C$5,sq_qm,$A$30)+C22*SUMIFS(sq_ru_l2_at_q,sq_struct_key,C$5,sq_qm,$A$30)+C23*SUMIFS(sq_ru_ev1_at_q,sq_struct_key,C$5,sq_qm,$A$30)+C24*SUMIFS(sq_ru_ev2_at_q,sq_struct_key,C$5,sq_qm,$A$30) | D36: =D21*SUMIFS(sq_ru_l1_at_q,sq_struct_key,D$5,sq_qm,$A$30)+D22*SUMIFS(sq_ru_l2_at_q,sq_struct_key,D$5,sq_qm,$A$30)+D23*SUMIFS(sq_ru_ev1_at_q,sq_struct_key,D$5,sq_qm,$A$30)+D24*SUMIFS(sq_ru_ev2_at_q,sq_struct_key,D$5,sq_qm,$A$30) | E36: =E21*SUMIFS(sq_ru_l1_at_q,sq_struct_key,E$5,sq_qm,$A$30)+E22*SUMIFS(sq_ru_l2_at_q,sq_struct_key,E$5,sq_qm,$A$30)+E23*SUMIFS(sq_ru_ev1_at_q,sq_struct_key,E$5,sq_qm,$A$30)+E24*SUMIFS(sq_ru_ev2_at_q,sq_struct_key,E$5,sq_qm,$A$30) | F36: =F21*SUMIFS(sq_ru_l1_at_q,sq_struct_key,F$5,sq_qm,$A$30)+F22*SUMIFS(sq_ru_l2_at_q,sq_struct_key,F$5,sq_qm,$A$30)+F23*SUMIFS(sq_ru_ev1_at_q,sq_struct_key,F$5,sq_qm,$A$30)+F24*SUMIFS(sq_ru_ev2_at_q,sq_struct_key,F$5,sq_qm,$A$30) | G36: =G21*SUMIFS(sq_ru_l1_at_q,sq_struct_key,G$5,sq_qm,$A$30)+G22*SUMIFS(sq_ru_l2_at_q,sq_struct_key,G$5,sq_qm,$A$30)+G23*SUMIFS(sq_ru_ev1_at_q,sq_struct_key,G$5,sq_qm,$A$30)+G24*SUMIFS(sq_ru_ev2_at_q,sq_struct_key,G$5,sq_qm,$A$30) | H36: =H21*SUMIFS(sq_ru_l1_at_q,sq_struct_key,H$5,sq_qm,$A$30)+H22*SUMIFS(sq_ru_l2_at_q,sq_struct_key,H$5,sq_qm,$A$30)+H23*SUMIFS(sq_ru_ev1_at_q,sq_struct_key,H$5,sq_qm,$A$30)+H24*SUMIFS(sq_ru_ev2_at_q,sq_struct_key,H$5,sq_qm,$A$30) | I36: =I21*SUMIFS(sq_ru_l1_at_q,sq_struct_key,I$5,sq_qm,$A$30)+I22*SUMIFS(sq_ru_l2_at_q,sq_struct_key,I$5,sq_qm,$A$30)+I23*SUMIFS(sq_ru_ev1_at_q,sq_struct_key,I$5,sq_qm,$A$30)+I24*SUMIFS(sq_ru_ev2_at_q,sq_struct_key,I$5,sq_qm,$A$30) | J36: =J21*SUMIFS(sq_ru_l1_at_q,sq_struct_key,J$5,sq_qm,$A$30)+J22*SUMIFS(sq_ru_l2_at_q,sq_struct_key,J$5,sq_qm,$A$30)+J23*SUMIFS(sq_ru_ev1_at_q,sq_struct_key,J$5,sq_qm,$A$30)+J24*SUMIFS(sq_ru_ev2_at_q,sq_struct_key,J$5,sq_qm,$A$30) | ... P36: =P21*SUMIFS(sq_ru_l1_at_q,sq_struct_key,P$5,sq_qm,$A$30)+P22*SUMIFS(sq_ru_l2_at_q,sq_struct_key,P$5,sq_qm,$A$30)+P23*SUMIFS(sq_ru_ev1_at_q,sq_struct_key,P$5,sq_qm,$A$30)+P24*SUMIFS(sq_ru_ev2_at_q,sq_struct_key,P$5,sq_qm,$A$30)
